Workbook

Sheet 10,2026
A2: MES | B2: OCTUBRE | C2: 2026 | W2: PRECIPITACIONES ACUMULADAS DEL 8/10/2026 AL 12/10/2026 (mm)
A3: DIA | B3: Posadas3 | C3: Posadas1 | D3: Cerro Azul2 | E3: El Soberbio (Aero)3 | F3: Campo Grande3 | G3: Santa Rita2 | H3: San Vicente3 | I3: San Pedro3 | J3: Valle Hermoso3 | K3: Bernardo de Irigoyen1 | L3: San Antonio2 | M3: Andresito Reserva3 | N3: Puerto Andresito3 | O3: Puerto Iguazú1 | T3: Oberá1 | W3: DIA | X3: POSADAS | Y3: CERRO AZUL | Z3: B. IRIGOYEN | AA3: P. IGUAZÚ
A4: 1 | B4: 0 | C4: 0 | D4: 0 | E4: 0 | F4: 0 | G4: 0 | I4: 3.6 | J4: 0.3 | K4: 21 | L4: 0 | M4: 31.8 | N4: 37.5 | O4: 5 | T4: 0 | W4: 46303 | X4: 32.4 | Y4: 23 | Z4: 0 | AA4: 0
A5: 2 | B5: 0 | C5: 0 | D5: 0 | E5: 0.2 | F5: 0 | G5: 0 | I5: 0 | J5: 0 | K5: 0 | L5: 0 | M5: 0.2 | N5: 0 | O5: 0.1 | T5: 0 | W5: 46304 | X5: 37.4 | Y5: 30 | Z5: 49 | AA5: 15
A6: 3 | B6: 0 | C6: 0 | D6: 0 | E6: 0 | F6: 0 | G6: 0 | I6: 0 | J6: 0 | K6: 0 | L6: 0 | M6: 0 | N6: 0 | O6: 0 | T6: 0 | W6: 46305 | X6: 47.4 | Y6: 36 | Z6: 10 | AA6: 11
A7: 4 | B7: 42.6 | C7: 50 | D7: 58 | E7: 44.8 | F7: 51 | G7: 86.5 | I7: 48 | J7: 33.5 | K7: 60 | M7: 54.6 | N7: 0 | O7: 73 | T7: ver | W7: 46306 | X7: 4 | Y7: 3 | Z7: 44 | AA7: 39
A8: 5 | B8: 0 | C8: 0 | D8: 0 | E8: 0 | F8: 0 | G8: 0 | I8: 0 | J8: 0.3 | K8: 0 | L8: 0 | M8: 0.2 | N8: 0 | O8: 0 | T8: 0 | W8: 46307 | X8: 17 | Y8: 5 | Z8: 25 | AA8: 81
A9: 6 | B9: 0 | C9: 0.1 | D9: 0.3 | E9: 6.6 | F9: 4.3 | G9: 0 | I9: 18.2 | J9: 19.3 | K9: 6 | M9: 2 | N9: 0 | O9: 0.1 | T9: 4 | W9: TOTAL | X9: =SUM(X4:X8) -> 138.2 | Y9: =SUM(Y4:Y8) -> 97 | Z9: =SUM(Z4:Z8) -> 128 | AA9: =SUM(AA4:AA8) -> 146
A10: 7 | B10: 0 | C10: 0 | D10: 0 | E10: 1.8 | F10: 0 | G10: 0 | I10: 0 | J10: 0 | K10: 0 | L10: 0 | M10: 2 | N10: 0 | O10: 0.1 | T10: 0
A11: 8 | B11: 48.8 | C11: 32.4 | D11: 23 | E11: 0 | F11: 0 | G11: 0 | I11: 0 | J11: 0 | K11: 0 | L11: 0 | M11: 0 | N11: 0 | O11: 0 | T11: 2
A12: 9 | B12: 22.6 | C12: 37.4 | D12: 30 | E12: 103.8 | F12: 74.5 | G12: 88 | I12: 64.2 | J12: 28 | K12: 49 | L12: 49 | M12: 28.2 | N12: 19.5 | O12: 15 | T12: 43
A13: 10 | B13: 49.2 | C13: 47.4 | D13: 36 | E13: 23.2 | F13: 20.8 | G13: 56.5 | I13: 12.8 | J13: 9.3 | K13: 10 | M13: 16.4 | N13: 15.5 | O13: 11 | T13: 37
A14: 11 | B14: 1.2 | C14: 4 | D14: 3 | E14: 9.8 | F14: 7.5 | G14: 19.5 | I14: 36.2 | J14: 26.3 | K14: 44 | L14: 84 | M14: 52 | N14: 136.3 | O14: 39 | T14: ver
A15: 12 | B15: 13.8 | C15: 17 | D15: 5 | E15: 5 | F15: 9.3 | G15: 7.5 | I15: 22.2 | J15: 24 | K15: 25 | L15: 35 | M15: 35.6 | N15: 16.8 | O15: 81
A16: 13 | B16: 78.8 | C16: 55 | D16: 41 | E16: 61.6 | F16: 54.8 | G16: 37 | I16: 53.2 | J16: 49 | K16: 55 | L16: 210 | M16: 54.8 | N16: 42 | O16: 52
A17: 14 | B17: 0.2 | C17: 0.1 | D17: 0.6 | E17: 0 | F17: 1.5 | I17: 24.6 | J17: 18.5 | K17: 50 | M17: 26.8 | O17: 31
A18: 15
A19: 16
A20: 17
A21: 18
A22: 19
A23: 20
A24: 21
A25: 22
A26: 23
A27: 24
A28: 25
A29: 26
... A34: 31
A35: TOTAL | B35: =SUM(B4:B34) -> 257.2 | C35: =SUM(C4:C34) -> 243.4 | D35: =SUM(D4:D34) -> 196.9 | E35: =SUM(E4:E34) -> 256.8 | F35: =SUM(F4:F34) -> 223.7 | G35: =SUM(G4:G34) -> 287.5 | H35: =SUM(H4:H34) -> 0 | I35: =SUM(I4:I34) -> 283 | ... T35: =SUM(T4:T34) -> 86
A36: MEDIA | B36: 253.4 | C36: 253.4 | D36: 227.6 | E36: 227.6 | F36: 227.6 | G36: 227.6 | H36: 227.6 | I36: 277.9 | J36: 247 | K36: 277.9 | L36: 277.9 | M36: 247 | N36: 247 | O36: 247 | T36: 0
E37: * | F37: * | G37: * | I37: ** | J37: *** | L37: ** | N37: ***
A38: ANOMALÍA | B38: =B35-B36 -> 3.8 | C38: =C35-C36 -> -10 | D38: =D35-D36 -> -30.7 | E38: =E35-E36 -> 29.2 | F38: =F35-F36 -> -3.9 | G38: =G35-G36 -> 59.9 | I38: =I35-I36 -> 5.1 | J38: =J35-J36 -> -38.5 | K38: =K35-K36 -> 42.1 | L38: =L35-L36 -> 100.1 | M38: =M35-M36 -> 57.6 | N38: =N35-N36 -> 20.6 | O38: =O35-O36 -> 60.3
A40: 1 Estaciones del SMN | G40: * se toma la media de Cerro Azul
A41: 2 Estaciones del INTA | G41: ** se toma la media de Bernardo de Irigoyen
A42: 3 Estaciones Automáticas | G42: *** se toma la media de Puerto Iguazú
A43: 4 Estaciones Red Matteo
F50: MONITOREO DE PRECIPITACIONES PROVINCIA DE MISIONES
C51: OCTUBRE | D51: 2026
C52: Posadas3 | D52: Posadas1 | E52: Cerro Azul2 | F52: El Soberbio (Aero)3 | G52: Campo Grande3 | H52: San Pedro3 | I52: Valle Hermoso3 | J52: Bernardo de Irigoyen1 | K52: Andresito Reserva3 | L52: Puerto Iguazú1
...

Sheet informe 13,10,26
F6: MONITOREO DE PRECIPITACIONES PROVINCIA DE MISIONES
C7: OCTUBRE | D7: 2026
C8: Posadas3 | D8: Posadas1 | E8: Cerro Azul2 | F8: El Soberbio (Aero)3 | G8: Campo Grande3 | H8: San Pedro3 | I8: Valle Hermoso3 | J8: Bernardo de Irigoyen1 | K8: Andresito Reserva3 | L8: Puerto Iguazú1
B9: 8/10-13/10 | C9: =SUM('10,2026'!B11:B16) -> 214.4 | D9: =SUM('10,2026'!C11:C16) -> 193.2 | E9: =SUM('10,2026'!D11:D16) -> 138 | F9: =SUM('10,2026'!E11:E16) -> 203.4 | G9: =SUM('10,2026'!F11:F16) -> 166.9 | H9: =SUM('10,2026'!I12:I16) -> 188.6 | I9: =SUM('10,2026'!J12:J16) -> 136.6 | J9: =SUM('10,2026'!K12:K16) -> 183 | K9: =SUM('10,2026'!M11:M16) -> 187 | L9: =SUM('10,2026'!O12:O16) -> 198
B10: MES | C10: 257 | D10: 243.3 | E10: 196.3 | F10: 256.8 | G10: 222.2 | H10: 258.4 | I10: 190 | J10: 270 | K10: 277.8 | L10: 276.3
B11: MEDIA | C11: 253.4 | D11: 253.4 | E11: 227.6 | F11: 227.6 | G11: 227.6 | H11: 277.9 | I11: 247 | J11: 277.9 | K11: 247 | L11: 247
B12: ANOMALÍA | C12: 3.6 | D12: -10.1 | E12: -31.3 | F12: 29.2 | G12: -5.4 | H12: -19.5 | I12: 57 | J12: -7.9 | K12: 30.8 | L12: 29.3
B14: 1 Estaciones del SMN | D14: 2 Estaciones del INTA | F14: 3 Estaciones Automáticas

Sheet 11,2026
